#VRML_SIM R2023b utf8

EXTERNPROTO "https://raw.githubusercontent.com/cyberbotics/webots/R2023b/projects/objects/backgrounds/protos/TexturedBackground.proto"
EXTERNPROTO "https://raw.githubusercontent.com/cyberbotics/webots/R2023b/projects/objects/backgrounds/protos/TexturedBackgroundLight.proto"
EXTERNPROTO "https://raw.githubusercontent.com/cyberbotics/webots/R2023b/projects/objects/floors/protos/RectangleArena.proto"
EXTERNPROTO "https://raw.githubusercontent.com/cyberbotics/webots/R2023b/projects/objects/lego/protos/LegoWheel.proto"
EXTERNPROTO "https://raw.githubusercontent.com/cyberbotics/webots/R2023b/projects/appearances/protos/Parquetry.proto"

WorldInfo {
}
Viewpoint {
  orientation 0.10078520320280208 0.78160744131646 -0.6155746506266373 0.4129461045056125
  position -4.435954509706624 2.1381183488484066 1.8026455395213243
}
TexturedBackground {
}
TexturedBackgroundLight {
}
RectangleArena {
  translation 0.16 0.28 0
  rotation 1 0 0 0
  floorSize 4 2.7
  floorAppearance PBRAppearance {
    roughnessMap ImageTexture {
      url [
        "https://raw.githubusercontent.com/cyberbotics/webots/R2023b/projects/appearances/protos/textures/parquetry/mosaic_parquetry_roughness.jpg"
      ]
    }
    metalness 0
    IBLStrength 40
    normalMap ImageTexture {
      url [
        "https://raw.githubusercontent.com/cyberbotics/webots/R2023b/projects/appearances/protos/textures/parquetry/mosaic_parquetry_normal.jpg"
      ]
    }
    occlusionMap ImageTexture {
      url [
        "https://raw.githubusercontent.com/cyberbotics/webots/R2023b/projects/appearances/protos/textures/parquetry/mosaic_parquetry_occlusion.jpg"
      ]
    }
  }
}
Robot {
  translation 1.41608 0.167498 0.07231
  rotation 7.270618726088165e-05 5.507251718997005e-05 -0.9999999958404141 -2.2898905570607546
  children [
    DEF SensorL DistanceSensor {
      translation 0.05 0.01 -0.04
      rotation 0 1 0 1.5708
      children [
        DEF Sensor Shape {
          appearance PBRAppearance {
            baseColor 0 0.8 1
            roughness 1
            metalness 0
          }
          geometry Box {
            size 0.015 0.015 0.015
          }
        }
      ]
      name "SensorL"
      boundingObject USE Sensor
      physics Physics {
      }
      type "infra-red"
    }
    DEF SensorR DistanceSensor {
      translation 0.05 -0.01 -0.04
      rotation 0 1 0 1.5708
      children [
        DEF Sensor Shape {
          appearance PBRAppearance {
            baseColor 0 0.8 1
            roughness 1
            metalness 0
          }
          geometry Box {
            size 0.015 0.015 0.015
          }
        }
      ]
      name "SensorR"
      boundingObject USE Sensor
      physics Physics {
      }
      type "infra-red"
    }
    DEF Sensor1 DistanceSensor {
      translation 0.05 0 0.01
      children [
        DEF Sensor Shape {
          appearance PBRAppearance {
            baseColor 0 0 1
            roughness 1
            metalness 0
          }
          geometry Box {
            size 0.015 0.015 0.015
          }
        }
      ]
      name "Sensor1(1)"
      boundingObject USE Sensor
      physics Physics {
      }
    }
    DEF Sensor2 DistanceSensor {
      translation 0.05 0.04 0.01
      rotation 0 0 1 0.7853996938995746
      children [
        DEF Sensor Shape {
          appearance PBRAppearance {
            baseColor 0 0 1
            roughness 1
            metalness 0
          }
          geometry Box {
            size 0.015 0.015 0.015
          }
        }
      ]
      name "Sensor2"
      boundingObject USE Sensor
      physics Physics {
      }
    }
    DEF Sensor3 DistanceSensor {
      translation 0 0.04 0.01
      rotation 0 0 1 1.57079633
      children [
        DEF Sensor Shape {
          appearance PBRAppearance {
            baseColor 0 0 1
            roughness 1
            metalness 0
          }
          geometry Box {
            size 0.015 0.015 0.015
          }
        }
      ]
      name "Sensor3"
      boundingObject USE Sensor
      physics Physics {
      }
    }
    DEF Sensor4 DistanceSensor {
      translation -0.05 0.04 0.01
      rotation 0 0 1 2.35619449
      children [
        DEF Sensor Shape {
          appearance PBRAppearance {
            baseColor 0 0 1
            roughness 1
            metalness 0
          }
          geometry Box {
            size 0.015 0.015 0.015
          }
        }
      ]
      name "Sensor4"
      boundingObject USE Sensor
      physics Physics {
      }
    }
    DEF Sensor5 DistanceSensor {
      translation -0.05 0 0.01
      rotation 0 0 1 3.14159265
      children [
        DEF Sensor Shape {
          appearance PBRAppearance {
            baseColor 0 0 1
            roughness 1
            metalness 0
          }
          geometry Box {
            size 0.015 0.015 0.015
          }
        }
      ]
      name "Sensor5"
      boundingObject USE Sensor
      physics Physics {
      }
    }
    DEF Sensor6 DistanceSensor {
      translation -0.05 -0.04 0.01
      rotation 0 0 1 -2.3561944871795863
      children [
        DEF Sensor Shape {
          appearance PBRAppearance {
            baseColor 0 0 1
            roughness 1
            metalness 0
          }
          geometry Box {
            size 0.015 0.015 0.015
          }
        }
      ]
      name "Sensor6"
      boundingObject USE Sensor
      physics Physics {
      }
    }
    DEF Sensor7 DistanceSensor {
      translation 0 -0.04 0.01
      rotation 0 0 1 -1.5707963271795862
      children [
        DEF Sensor Shape {
          appearance PBRAppearance {
            baseColor 0 0 1
            roughness 1
            metalness 0
          }
          geometry Box {
            size 0.015 0.015 0.015
          }
        }
      ]
      name "Sensor7"
      boundingObject USE Sensor
      physics Physics {
      }
    }
    DEF Sensor8 DistanceSensor {
      translation 0.05 -0.04 0.01
      rotation 0 0 1 -0.7853996938995746
      children [
        DEF Sensor Shape {
          appearance PBRAppearance {
            baseColor 0 0 1
            roughness 1
            metalness 0
          }
          geometry Box {
            size 0.015 0.015 0.015
          }
        }
      ]
      name "Sensor8"
      boundingObject USE Sensor
      physics Physics {
      }
    }
    DEF Right2 HingeJoint {
      jointParameters HingeJointParameters {
        position 64114.32855395295
        axis 0 1 0
        anchor 0.03 -0.05 -0.05
      }
      device [
        RotationalMotor {
          name "Right2"
        }
      ]
      endPoint LegoWheel {
        translation 0.029997900348943327 -0.050000000400255304 -0.04999853188045716
        rotation 0.015394852439955064 0.9997344555086375 0.017146923549142917 0.7057599210859147
        name "Right2"
      }
    }
    DEF Left2 HingeJoint {
      jointParameters HingeJointParameters {
        position 104725.08679361084
        axis 0 1 0
        anchor 0.03 0.05 -0.05
      }
      device [
        RotationalMotor {
          name "Left2"
        }
      ]
      endPoint LegoWheel {
        translation 0.029999704454177156 0.049999999608291545 -0.04999751037988066
        rotation -0.003282809513688802 0.9999686651122053 -0.007203607111108082 3.23728018665755
        name "Left2"
      }
    }
    DEF Right1 HingeJoint {
      jointParameters HingeJointParameters {
        position 64112.212365069594
        axis 0 1 0
        anchor -0.03 -0.05 -0.05
      }
      device [
        RotationalMotor {
          name "Right1"
        }
      ]
      endPoint LegoWheel {
        translation -0.030002038578015897 -0.05000000038863325 -0.0499985740693159
        rotation 0.011959252337048245 -0.9999249373003349 -0.002663840922439728 1.410675289124556
        name "Right1"
      }
    }
    DEF Left1 HingeJoint {
      jointParameters HingeJointParameters {
        position 104725.08895769942
        axis 0 1 0
        anchor -0.03 0.05 -0.05
      }
      device [
        RotationalMotor {
          name "Left1"
        }
      ]
      endPoint LegoWheel {
        translation -0.03000029915928379 0.049999999602955675 -0.04999747615415281
        rotation -0.003276022781699856 0.9999686626020705 -0.007207044370636404 3.2394442061622026
        name "Left1"
      }
    }
    DEF RobotBody Shape {
      appearance PBRAppearance {
        baseColor 1 0.4 0
        roughness 1
        metalness 0
      }
      geometry Box {
        size 0.1 0.08 0.08
      }
    }
  ]
  boundingObject USE RobotBody
  physics Physics {
  }
  controller "LineFollow"
}
Transform {
  translation 1 1 0
  scale 0.03 0.03 0.02
  children [
    Shape {
      appearance Parquetry {
        type "dark strip"
        colorOverride 0 0 0
        IBLStrength 0.01
      }
      geometry Mesh {
        url [
          "../tinker.obj"
        ]
      }
    }
  ]
}
